Workbook
Name DK: #REF!,#REF!
Name j__200시프복사할걸아마: #REF!
Name J_200: #REF!
Name T_200: #REF!
Name t200복사할것: #REF!,#REF!,#REF!,#REF!,#REF!,#REF!,#REF!,#REF!,#REF!
Name V_210: #REF!
Name ㅁ1: #REF!
Name 메롱: #REF!,#REF!
Name 변기연: #REF!
Name 복사: #REF!
Name 전일계획: #REF!,#REF!

Sheet 1
A1: 원가계산서
A2: 작성일자 : 25.01.14 | C2: 작성자 : 최유정
A3: 차종 | B3: CE FL | D3: 고 객 품 번 | F3: 00370070 | H3: 경 림 품 번 | I3: WA-2312-1111 | K3: 품 명 | L3: CE FL HL STD MAIN DOM/EC LD WIRE
A4: SOP | B4: 2025.05.15 | D4: 연 생 산 수 량 | H4: 고 객 사 | I4: SL 천안공장 | K4: EO NO | L4: DS-24163 | N4: ECO 일자 | O4: 24.12.04
A6: 3. 원가 계산 정보
A7: 원 가 요 소 | C7: 계 산 수 식 | F7: 외작 | G7: 내작 | H7: 계 | I7: 협력사 구매가 | K7: 비고 | U7: 원 가 요 소 | W7: 외작 | X7: 내작 | Y7: 계 | Z7: 협력사 구매가
A8: 1. 재 료 비 | C8: 재료비 합계(내/외작) | F8: =SUMIF($I$29:$I$101,F$7,$S$29:$S$101) -> 1609.45 | G8: =SUMIF($I$29:$I$101,G$7,$S$29:$S$101) -> 839.89 | H8: =+F8+G8 -> 2449.34 | I8: =SUM($S$29:$S$101) -> 2449.34 | U8: 1. 재 료 비 | W8: =SUMIF($T$29:$T$101,W$7,$Z$29:$Z$101) -> 0 | X8: =SUMIF($T$29:$T$101,X$7,$Z$29:$Z$101) -> 0 | Y8: =+W8+X8 -> 0 | Z8: =SUM($Z$29:$Z$101) -> 0
A9: 2. 가공비 | F9: =+F10+F11 -> 1142.76 | G9: =+G10+G11 -> 195.52 | H9: =+F9+G9 -> 1338.28 | I9: =SUM(I10:I11) -> 1142.76 | U9: 2. 가공비 | W9: =+W10+W11 -> 0 | X9: =+X10+X11 -> 0 | Y9: =+W9+X9 -> 0 | Z9: =SUM(Z10:Z11) -> 0
A10: 2. 노 무 비 | C10: 노무비 합계(내/외작) | F10: =SUMIF($I$109:$I$154,F$7,$Q$109:$Q$154) -> 1138.9 | G10: =SUMIF($I$109:$I$154,G$7,$Q$109:$Q$154) -> 165.87 | H10: =+F10+G10 -> 1304.77 | I10: =SUMIF($I$109:$I$154,$F$7,$Q$109:$Q$154) -> 1138.9 | U10: 2. 노 무 비 | W10: =SUMIF($T$109:$T$154,W$7,$X$109:$X$154) -> 0 | X10: =SUMIF($T$109:$T$154,X$7,$X$109:$X$154) -> 0 | Y10: =+W10+X10 -> 0 | Z10: =SUMIF($T$109:$T$154,$W$7,$X$109:$X$154) -> 0
A11: 3. 경 비 | C11: 경비 합계(내/외작) | F11: =SUMIF($I$109:$I$154,F$7,$R$109:$R$154) -> 3.86 | G11: =SUMIF($I$109:$I$154,G$7,$R$109:$R$154) -> 29.65 | H11: =+F11+G11 -> 33.51 | I11: =SUMIF($I$109:$I$154,$F$7,$R$109:$R$154) -> 3.86 | U11: 3. 경 비 | W11: =SUMIF($T$109:$T$154,W$7,$Y$109:$Y$154) -> 0 | X11: =SUMIF($T$109:$T$154,X$7,$Y$109:$Y$154) -> 0 | Y11: =+W11+X11 -> 0 | Z11: =SUMIF($T$109:$T$154,$W$7,$Y$109:$Y$154) -> 0
A12: 4. 제 조 원 가 | C12: ( 1 + 2 + 3 ) | F12: =+F8+F10+F11 -> 2752.21 | G12: =+G8+G10+G11 -> 1035.41 | H12: =+F12+G12 -> 3787.62 | I12: =SUM(I11,I10,I8) -> 3592.1 | U12: 4. 제 조 원 가 | W12: =+W8+W10+W11 -> 0 | X12: =+X8+X10+X11 -> 0 | Y12: =+W12+X12 -> 0 | Z12: =SUM(Z8,Z10,Z11) -> 0
A13: 5. 재 료 관 리 비 | C13: ( 1 ) X | D13: 0.01 | F13: =ROUND(+F8*$D13,2) -> 16.09 | G13: =ROUND(+G8*$D13,2) -> 8.4 | H13: =+F13+G13 -> 24.49 | I13: =ROUND(I8*$D13,2) -> 24.49 | U13: 5. 재 료 관 리 비 | W13: =ROUND(+W8*$D13,2) -> 0 | X13: =ROUND(+X8*$D13,2) -> 0 | Y13: =+W13+X13 -> 0 | Z13: =ROUND(Z8*$D13,2) -> 0
A14: 6. 일 반 관 리 비 | C14: ( 2+3 ) X | D14: 0.1 | F14: =ROUND((F10+F11)*$D14,2) -> 114.28 | G14: =ROUND((G10+G11)*$D14,2) -> 19.55 | H14: =+F14+G14 -> 133.83 | I14: =ROUND((I10+I11)*$D14,2) -> 114.28 | U14: 6. 일 반 관 리 비 | W14: =ROUND((W10+W11)*$D14,2) -> 0 | X14: =ROUND((X10+X11)*$D14,2) -> 0 | Y14: =+W14+X14 -> 0 | Z14: =ROUND((Z10+Z11)*$D14,2) -> 0
A15: 7. 불 량 비 | C15: ( 4 ) X | D15: 0.01 | F15: =ROUND(F12*$D15,2) -> 27.52 | G15: =ROUND(G12*$D15,2) -> 10.35 | H15: =+F15+G15 -> 37.87 | I15: =ROUND(I12*$D15,2) -> 35.92 | U15: 7. 불 량 비 | W15: =ROUND(W12*$D15,2) -> 0 | X15: =ROUND(X12*$D15,2) -> 0 | Y15: =+W15+X15 -> 0 | Z15: =ROUND(Z12*$D15,2) -> 0
A16: 8. 이 윤 | C16: ( 2 +3+ 6 ) X | D16: 0.1 | F16: =ROUND(SUM(F10,F11,F14)*$D16,2) -> 125.7 | G16: =ROUND(SUM(G10,G11,G14)*$D16,2) -> 21.51 | H16: =+F16+G16 -> 147.21 | I16: =ROUND((I10+I11+I14)*$D16,2) -> 125.7 | U16: 8. 이 윤 | W16: =ROUND(SUM(W10,W11,W14)*$D16,2) -> 0 | X16: =ROUND(SUM(X10,X11,X14)*$D16,2) -> 0 | Y16: =+W16+X16 -> 0 | Z16: =ROUND((Z10+Z11+Z14)*$D16,2) -> 0
A17: 9. 포 장 비 | C17: 별도 | U17: 9. 포 장 비
A18: 10. 운 반 비 | C18: 별도 | U18: 10. 운 반 비
A19: 11. 구 매 원 가 | C19: 별도 | F19: =SUM(F12:F18) -> 3035.8 | G19: =SUM(G12:G18) -> 1095.22 | H19: =SUM(H12:H18) -> 4131.02 | I19: =SUM(I12:I18) -> 3892.49 | U19: 11. 구 매 원 가 | W19: =SUM(W12:W18) -> 0 | X19: =SUM(X12:X18) -> 0 | Y19: =SUM(Y12:Y18) -> 0 | Z19: =SUM(Z12:Z18) -> 0
A20: 12. 설 계 시 험 비 | F20: =ROUND(+F19*$D20,2) -> 0 | G20: =ROUND(+G19*$D20,2) -> 0 | H20: =G20+F20 -> 0 | I20: =H20+G20 -> 0 | U20: 12. 설 계 시 험 비 | W20: 0 | X20: 0 | Y20: 0 | Z20: 0
A21: 13. 관 리 비 | F21: =ROUND(F19*$D21,2) -> 0 | G21: =ROUND(G19*$D21,2) -> 0 | H21: =SUM(H12:H18)*$D21 -> 0 | I21: =SUM(I12:I18)*$D21 -> 0 | U21: 13. 관 리 비 | W21: 0 | X21: 0 | Y21: 0 | Z21: 0
A22: 14. 총 원 가 | F22: =SUM(F19:F21) -> 3035.8 | G22: =SUM(G19:G21) -> 1095.22 | H22: =SUM(H19:H21) -> 4131.02 | I22: =SUM(I19:I21) -> 3892.49 | U22: 14. 총 원 가 | W22: =SUM(W19:W21) -> 0 | X22: =SUM(X19:X21) -> 0 | Y22: =SUM(Y19:Y21) -> 0 | Z22: =SUM(Z19:Z21) -> 0
A23: 판 매 가 | U23: 판 매 가
A26: 1. 재료비 상세내역
A27: NO | B27: 품 번 | D27: 품 번 | F27: 품 명 | I27: 내외작 | J27: 규격 | T27: 내외작 | AA27: 차이 | AB27: 비 고
B28: (절압품) | D28: (원재료) | F28: (원재료 품명) | N28: 단위 | O28: 수량 | P28: 단가 | Q28: 재료비 | R28: SCRAP비 | S28: 합계 | U28: 단위 | V28: 수량 | W28: 단가 | X28: 재료비 | Y28: SCRAP비 | Z28: 합계
A29: =ROW(A29)-28 -> 1 | B29: 00370070-001 | D29: 210-8613 | F29: AESSXF 0.3 B/R | I29: 내작 | J29: WIRE | N29: MTR | O29: 0.4075 | P29: =VLOOKUP($D29,'[1]250113_자재단가조회'!$D$2:$M$517,10,0) -> 60.65 | Q29: =ROUND(O29*P29,2) -> 24.71 | S29: =Q29+R29 -> 24.71 | X29: =ROUND(V29*W29,2) -> 0 | Z29: =X29+Y29 -> 0 | AB29: 전선길이 220mm 증가
A30: =ROW(A30)-28 -> 2 | B30: 00370070-001 | D30: 251-3107 | F30: KH2000016-21 | I30: 내작 | J30: TERMINAL | N30: EA | O30: 1 | P30: =VLOOKUP($D30,'[1]250113_자재단가조회'!$D$2:$M$517,10,0) -> 8.5 | Q30: =ROUND(O30*P30,2) -> 8.5 | S30: =Q30+R30 -> 8.5
A31: =ROW(A31)-28 -> 3 | B31: 00370070-001 | D31: 251-2143 | F31: 731409-7 | I31: 내작 | J31: TERMINAL | N31: EA | O31: 1 | P31: =VLOOKUP($D31,'[1]250113_자재단가조회'!$D$2:$M$517,10,0) -> 8 | Q31: =ROUND(O31*P31,2) -> 8 | S31: =Q31+R31 -> 8
A32: =ROW(A32)-28 -> 4 | B32: 00370070-002 | D32: 210-8615 | F32: AESSXF 0.3 B/O | I32: 내작 | J32: WIRE | N32: MTR | O32: 0.4075 | P32: =VLOOKUP($D32,'[1]250113_자재단가조회'!$D$2:$M$517,10,0) -> 60.65 | Q32: =ROUND(O32*P32,2) -> 24.71 | S32: =Q32+R32 -> 24.71 | AB32: 전선길이 220mm 증가
A33: =ROW(A33)-28 -> 5 | B33: 00370070-002 | D33: 251-3107 | F33: KH2000016-21 | I33: 내작 | J33: TERMINAL | N33: EA | O33: 1 | P33: =VLOOKUP($D33,'[1]250113_자재단가조회'!$D$2:$M$517,10,0) -> 8.5 | Q33: =ROUND(O33*P33,2) -> 8.5 | S33: =Q33+R33 -> 8.5
A34: =ROW(A34)-28 -> 6 | B34: 00370070-002 | D34: 251-2143 | F34: 731409-7 | I34: 내작 | J34: TERMINAL | N34: EA | O34: 1 | P34: =VLOOKUP($D34,'[1]250113_자재단가조회'!$D$2:$M$517,10,0) -> 8 | Q34: =ROUND(O34*P34,2) -> 8 | S34: =Q34+R34 -> 8
A35: =ROW(A35)-28 -> 7 | B35: 00370070-003 | D35: 210-8614 | F35: AESSXF 0.3 B/Y | I35: 내작 | J35: WIRE | N35: MTR | O35: 0.4075 | P35: =VLOOKUP($D35,'[1]250113_자재단가조회'!$D$2:$M$517,10,0) -> 60.65 | Q35: =ROUND(O35*P35,2) -> 24.71 | S35: =Q35+R35 -> 24.71 | AB35: 전선길이 220mm 증가
A36: =ROW(A36)-28 -> 8 | B36: 00370070-003 | D36: 251-3107 | F36: KH2000016-21 | I36: 내작 | J36: TERMINAL | N36: EA | O36: 1 | P36: =VLOOKUP($D36,'[1]250113_자재단가조회'!$D$2:$M$517,10,0) -> 8.5 | Q36: =ROUND(O36*P36,2) -> 8.5 | S36: =Q36+R36 -> 8.5
A37: =ROW(A37)-28 -> 9 | B37: 00370070-003 | D37: 251-2143 | F37: 731409-7 | I37: 내작 | J37: TERMINAL | N37: EA | O37: 1 | P37: =VLOOKUP($D37,'[1]250113_자재단가조회'!$D$2:$M$517,10,0) -> 8 | Q37: =ROUND(O37*P37,2) -> 8 | S37: =Q37+R37 -> 8
A38: =ROW(A38)-28 -> 10 | B38: 00370070-004 | D38: 210-8621 | F38: AESSXF 0.3 B/G | I38: 내작 | J38: WIRE | N38: MTR | O38: 0.4075 | P38: =VLOOKUP($D38,'[1]250113_자재단가조회'!$D$2:$M$517,10,0) -> 60.65 | Q38: =ROUND(O38*P38,2) -> 24.71 | S38: =Q38+R38 -> 24.71 | AB38: 전선길이 220mm 증가
A39: =ROW(A39)-28 -> 11 | B39: 00370070-004 | D39: 251-3107 | F39: KH2000016-21 | I39: 내작 | J39: TERMINAL | N39: EA | O39: 1 | P39: =VLOOKUP($D39,'[1]250113_자재단가조회'!$D$2:$M$517,10,0) -> 8.5 | Q39: =ROUND(O39*P39,2) -> 8.5 | S39: =Q39+R39 -> 8.5
A40: =ROW(A40)-28 -> 12 | B40: 00370070-004 | D40: 251-2143 | F40: 731409-7 | I40: 내작 | J40: TERMINAL | N40: EA | O40: 1 | P40: =VLOOKUP($D40,'[1]250113_자재단가조회'!$D$2:$M$517,10,0) -> 8 | Q40: =ROUND(O40*P40,2) -> 8 | S40: =Q40+R40 -> 8
A41: =ROW(A41)-28 -> 13 | B41: 00370070-005 | D41: 210-8625 | F41: AESSXF 0.3 Gr/R | I41: 내작 | J41: WIRE | N41: MTR | O41: 0.4075 | P41: =VLOOKUP($D41,'[1]250113_자재단가조회'!$D$2:$M$517,10,0) -> 60.65 | Q41: =ROUND(O41*P41,2) -> 24.71 | S41: =Q41+R41 -> 24.71 | AB41: 전선길이 220mm 증가
A42: =ROW(A42)-28 -> 14 | B42: 00370070-005 | D42: 251-3107 | F42: KH2000016-21 | I42: 내작 | J42: TERMINAL | N42: EA | O42: 1 | P42: =VLOOKUP($D42,'[1]250113_자재단가조회'!$D$2:$M$517,10,0) -> 8.5 | Q42: =ROUND(O42*P42,2) -> 8.5 | S42: =Q42+R42 -> 8.5
A43: =ROW(A43)-28 -> 15 | B43: 00370070-005 | D43: 251-2143 | F43: 731409-7 | I43: 내작 | J43: TERMINAL | N43: EA | O43: 1 | P43: =VLOOKUP($D43,'[1]250113_자재단가조회'!$D$2:$M$517,10,0) -> 8 | Q43: =ROUND(O43*P43,2) -> 8 | S43: =Q43+R43 -> 8
...

Sheet 2
A1: 원가계산서
A2: 작성일자 : 25.01.14 | C2: 작성자 : 최유정
A3: 차종 | B3: CE FL | D3: 고 객 품 번 | F3: 00370071 | H3: 경 림 품 번 | I3: WA-2312-1211 | K3: 품 명 | L3: CE FL HL STD MAIN DOM/EC NON LD WIRE
A4: SOP | B4: 2025.05.15 | D4: 연 생 산 수 량 | H4: 고 객 사 | I4: SL 천안공장 | K4: EO NO | L4: DS-24163 | N4: ECO 일자 | O4: 24.12.04
A6: 3. 원가 계산 정보
A7: 원 가 요 소 | C7: 계 산 수 식 | F7: 외작 | G7: 내작 | H7: 계 | I7: 협력사 구매가 | K7: 비고 | U7: 원 가 요 소 | W7: 외작 | X7: 내작 | Y7: 계 | Z7: 협력사 구매가
A8: 1. 재 료 비 | C8: 재료비 합계(내/외작) | F8: =SUMIF($I$29:$I$91,F$7,$S$29:$S$91) -> 1531.97 | G8: =SUMIF($I$29:$I$91,G$7,$S$29:$S$91) -> 727.42 | H8: =+F8+G8 -> 2259.39 | I8: =SUM($S$29:$S$91) -> 2259.39 | U8: 1. 재 료 비 | W8: =SUMIF($T$29:$T$91,W$7,$Z$29:$Z$91) -> 0 | X8: =SUMIF($T$29:$T$91,X$7,$Z$29:$Z$91) -> 0 | Y8: =+W8+X8 -> 0 | Z8: =SUM($Z$29:$Z$91) -> 0
A9: 2. 가공비 | F9: =+F10+F11 -> 999.8 | G9: =+G10+G11 -> 168.16 | H9: =+F9+G9 -> 1167.96 | I9: =SUM(I10:I11) -> 999.8 | U9: 2. 가공비 | W9: =+W10+W11 -> 0 | X9: =+X10+X11 -> 0 | Y9: =+W9+X9 -> 0 | Z9: =SUM(Z10:Z11) -> 0
A10: 2. 노 무 비 | C10: 노무비 합계(내/외작) | F10: =SUMIF($I$99:$I$139,F$7,$Q$99:$Q$139) -> 996.54 | G10: =SUMIF($I$99:$I$139,G$7,$Q$99:$Q$139) -> 142.92 | H10: =+F10+G10 -> 1139.46 | I10: =SUMIF($I$99:$I$139,$F$7,$Q$99:$Q$139) -> 996.54 | U10: 2. 노 무 비 | W10: =SUMIF($T$99:$T$139,W$7,$X$99:$X$139) -> 0 | X10: =SUMIF($T$99:$T$139,X$7,$X$99:$X$139) -> 0 | Y10: =+W10+X10 -> 0 | Z10: =SUMIF($T$99:$T$139,$W$7,$X$99:$X$139) -> 0
A11: 3. 경 비 | C11: 경비 합계(내/외작) | F11: =SUMIF($I$99:$I$139,F$7,$R$99:$R$139) -> 3.26 | G11: =SUMIF($I$99:$I$139,G$7,$R$99:$R$139) -> 25.24 | H11: =+F11+G11 -> 28.5 | I11: =SUMIF($I$99:$I$139,$F$7,$R$99:$R$139) -> 3.26 | U11: 3. 경 비 | W11: =SUMIF($T$99:$T$139,W$7,$Y$99:$Y$139) -> 0 | X11: =SUMIF($T$99:$T$139,X$7,$Y$99:$Y$139) -> 0 | Y11: =+W11+X11 -> 0 | Z11: =SUMIF($T$99:$T$139,$W$7,$Y$99:$Y$139) -> 0
A12: 4. 제 조 원 가 | C12: ( 1 + 2 + 3 ) | F12: =+F8+F10+F11 -> 2531.77 | G12: =+G8+G10+G11 -> 895.58 | H12: =+F12+G12 -> 3427.35 | I12: =SUM(I11,I10,I8) -> 3259.19 | U12: 4. 제 조 원 가 | W12: =+W8+W10+W11 -> 0 | X12: =+X8+X10+X11 -> 0 | Y12: =+W12+X12 -> 0 | Z12: =SUM(Z8,Z10,Z11) -> 0
A13: 5. 재 료 관 리 비 | C13: ( 1 ) X | D13: 0.01 | F13: =ROUND(+F8*$D13,2) -> 15.32 | G13: =ROUND(+G8*$D13,2) -> 7.27 | H13: =+F13+G13 -> 22.59 | I13: =ROUND(I8*$D13,2) -> 22.59 | U13: 5. 재 료 관 리 비 | W13: =ROUND(+W8*$D13,2) -> 0 | X13: =ROUND(+X8*$D13,2) -> 0 | Y13: =+W13+X13 -> 0 | Z13: =ROUND(Z8*$D13,2) -> 0
A14: 6. 일 반 관 리 비 | C14: ( 2+3 ) X | D14: 0.1 | F14: =ROUND((F10+F11)*$D14,2) -> 99.98 | G14: =ROUND((G10+G11)*$D14,2) -> 16.82 | H14: =+F14+G14 -> 116.8 | I14: =ROUND((I10+I11)*$D14,2) -> 99.98 | U14: 6. 일 반 관 리 비 | W14: =ROUND((W10+W11)*$D14,2) -> 0 | X14: =ROUND((X10+X11)*$D14,2) -> 0 | Y14: =+W14+X14 -> 0 | Z14: =ROUND((Z10+Z11)*$D14,2) -> 0
A15: 7. 불 량 비 | C15: ( 4 ) X | D15: 0.01 | F15: =ROUND(F12*$D15,2) -> 25.32 | G15: =ROUND(G12*$D15,2) -> 8.96 | H15: =+F15+G15 -> 34.28 | I15: =ROUND(I12*$D15,2) -> 32.59 | U15: 7. 불 량 비 | W15: =ROUND(W12*$D15,2) -> 0 | X15: =ROUND(X12*$D15,2) -> 0 | Y15: =+W15+X15 -> 0 | Z15: =ROUND(Z12*$D15,2) -> 0
A16: 8. 이 윤 | C16: ( 2 +3+ 6 ) X | D16: 0.1 | F16: =ROUND(SUM(F10,F11,F14)*$D16,2) -> 109.98 | G16: =ROUND(SUM(G10,G11,G14)*$D16,2) -> 18.5 | H16: =+F16+G16 -> 128.48 | I16: =ROUND((I10+I11+I14)*$D16,2) -> 109.98 | U16: 8. 이 윤 | W16: =ROUND(SUM(W10,W11,W14)*$D16,2) -> 0 | X16: =ROUND(SUM(X10,X11,X14)*$D16,2) -> 0 | Y16: =+W16+X16 -> 0 | Z16: =ROUND((Z10+Z11+Z14)*$D16,2) -> 0
A17: 9. 포 장 비 | C17: 별도 | U17: 9. 포 장 비
A18: 10. 운 반 비 | C18: 별도 | U18: 10. 운 반 비
A19: 11. 구 매 원 가 | C19: 별도 | F19: =SUM(F12:F18) -> 2782.37 | G19: =SUM(G12:G18) -> 947.13 | H19: =SUM(H12:H18) -> 3729.5 | I19: =SUM(I12:I18) -> 3524.33 | U19: 11. 구 매 원 가 | W19: =SUM(W12:W18) -> 0 | X19: =SUM(X12:X18) -> 0 | Y19: =SUM(Y12:Y18) -> 0 | Z19: =SUM(Z12:Z18) -> 0
A20: 12. 설 계 시 험 비 | F20: =ROUND(+F19*$D20,2) -> 0 | G20: =ROUND(+G19*$D20,2) -> 0 | H20: =G20+F20 -> 0 | I20: =H20+G20 -> 0 | U20: 12. 설 계 시 험 비 | W20: 0 | X20: 0 | Y20: 0 | Z20: 0
A21: 13. 관 리 비 | F21: =ROUND(F19*$D21,2) -> 0 | G21: =ROUND(G19*$D21,2) -> 0 | H21: =SUM(H12:H18)*$D21 -> 0 | I21: =SUM(I12:I18)*$D21 -> 0 | U21: 13. 관 리 비 | W21: 0 | X21: 0 | Y21: 0 | Z21: 0
A22: 14. 총 원 가 | F22: =SUM(F19:F21) -> 2782.37 | G22: =SUM(G19:G21) -> 947.13 | H22: =SUM(H19:H21) -> 3729.5 | I22: =SUM(I19:I21) -> 3524.33 | U22: 14. 총 원 가 | W22: =SUM(W19:W21) -> 0 | X22: =SUM(X19:X21) -> 0 | Y22: =SUM(Y19:Y21) -> 0 | Z22: =SUM(Z19:Z21) -> 0
A23: 판 매 가 | U23: 판 매 가
A26: 1. 재료비 상세내역
A27: NO | B27: 품 번 | D27: 품 번 | F27: 품 명 | I27: 내외작 | J27: 규격 | T27: 내외작 | AA27: 차이
B28: (절압품) | D28: (원재료) | F28: (원재료 품명) | N28: 단위 | O28: 수량 | P28: 단가 | Q28: 재료비 | R28: SCRAP비 | S28: 합계 | U28: 단위 | V28: 수량 | W28: 단가 | X28: 재료비 | Y28: SCRAP비 | Z28: 합계
A29: =ROW(A29)-28 -> 1 | B29: 00370071-001 | D29: 210-8613 | F29: AESSXF 0.3 B/R | I29: 내작 | J29: WIRE | N29: MTR | O29: 0.4075 | P29: =VLOOKUP($D29,'[1]250113_자재단가조회'!$D$2:$M$517,10,0) -> 60.65 | Q29: =ROUND(O29*P29,2) -> 24.71 | S29: =Q29+R29 -> 24.71 | X29: =ROUND(V29*W29,2) -> 0 | Z29: =X29+Y29 -> 0 | AB29: 전선길이 220mm 증가
A30: =ROW(A30)-28 -> 2 | B30: 00370071-001 | D30: 251-3107 | F30: KH2000016-21 | I30: 내작 | J30: TERMINAL | N30: EA | O30: 1 | P30: =VLOOKUP($D30,'[1]250113_자재단가조회'!$D$2:$M$517,10,0) -> 8.5 | Q30: =ROUND(O30*P30,2) -> 8.5 | S30: =Q30+R30 -> 8.5
A31: =ROW(A31)-28 -> 3 | B31: 00370071-001 | D31: 251-2143 | F31: 731409-7 | I31: 내작 | J31: TERMINAL | N31: EA | O31: 1 | P31: =VLOOKUP($D31,'[1]250113_자재단가조회'!$D$2:$M$517,10,0) -> 8 | Q31: =ROUND(O31*P31,2) -> 8 | S31: =Q31+R31 -> 8
A32: =ROW(A32)-28 -> 4 | B32: 00370071-002 | D32: 210-8615 | F32: AESSXF 0.3 B/O | I32: 내작 | J32: WIRE | N32: MTR | O32: 0.4075 | P32: =VLOOKUP($D32,'[1]250113_자재단가조회'!$D$2:$M$517,10,0) -> 60.65 | Q32: =ROUND(O32*P32,2) -> 24.71 | S32: =Q32+R32 -> 24.71 | AB32: 전선길이 220mm 증가
A33: =ROW(A33)-28 -> 5 | B33: 00370071-002 | D33: 251-3107 | F33: KH2000016-21 | I33: 내작 | J33: TERMINAL | N33: EA | O33: 1 | P33: =VLOOKUP($D33,'[1]250113_자재단가조회'!$D$2:$M$517,10,0) -> 8.5 | Q33: =ROUND(O33*P33,2) -> 8.5 | S33: =Q33+R33 -> 8.5
A34: =ROW(A34)-28 -> 6 | B34: 00370071-002 | D34: 251-2143 | F34: 731409-7 | I34: 내작 | J34: TERMINAL | N34: EA | O34: 1 | P34: =VLOOKUP($D34,'[1]250113_자재단가조회'!$D$2:$M$517,10,0) -> 8 | Q34: =ROUND(O34*P34,2) -> 8 | S34: =Q34+R34 -> 8
A35: =ROW(A35)-28 -> 7 | B35: 00370071-003 | D35: 210-8614 | F35: AESSXF 0.3 B/Y | I35: 내작 | J35: WIRE | N35: MTR | O35: 0.4075 | P35: =VLOOKUP($D35,'[1]250113_자재단가조회'!$D$2:$M$517,10,0) -> 60.65 | Q35: =ROUND(O35*P35,2) -> 24.71 | S35: =Q35+R35 -> 24.71 | AB35: 전선길이 220mm 증가
A36: =ROW(A36)-28 -> 8 | B36: 00370071-003 | D36: 251-3107 | F36: KH2000016-21 | I36: 내작 | J36: TERMINAL | N36: EA | O36: 1 | P36: =VLOOKUP($D36,'[1]250113_자재단가조회'!$D$2:$M$517,10,0) -> 8.5 | Q36: =ROUND(O36*P36,2) -> 8.5 | S36: =Q36+R36 -> 8.5
A37: =ROW(A37)-28 -> 9 | B37: 00370071-003 | D37: 251-2143 | F37: 731409-7 | I37: 내작 | J37: TERMINAL | N37: EA | O37: 1 | P37: =VLOOKUP($D37,'[1]250113_자재단가조회'!$D$2:$M$517,10,0) -> 8 | Q37: =ROUND(O37*P37,2) -> 8 | S37: =Q37+R37 -> 8
A38: =ROW(A38)-28 -> 10 | B38: 00370071-004 | D38: 210-8621 | F38: AESSXF 0.3 B/G | I38: 내작 | J38: WIRE | N38: MTR | O38: 0.4075 | P38: =VLOOKUP($D38,'[1]250113_자재단가조회'!$D$2:$M$517,10,0) -> 60.65 | Q38: =ROUND(O38*P38,2) -> 24.71 | S38: =Q38+R38 -> 24.71 | AB38: 전선길이 220mm 증가
A39: =ROW(A39)-28 -> 11 | B39: 00370071-004 | D39: 251-3107 | F39: KH2000016-21 | I39: 내작 | J39: TERMINAL | N39: EA | O39: 1 | P39: =VLOOKUP($D39,'[1]250113_자재단가조회'!$D$2:$M$517,10,0) -> 8.5 | Q39: =ROUND(O39*P39,2) -> 8.5 | S39: =Q39+R39 -> 8.5
A40: =ROW(A40)-28 -> 12 | B40: 00370071-004 | D40: 251-2143 | F40: 731409-7 | I40: 내작 | J40: TERMINAL | N40: EA | O40: 1 | P40: =VLOOKUP($D40,'[1]250113_자재단가조회'!$D$2:$M$517,10,0) -> 8 | Q40: =ROUND(O40*P40,2) -> 8 | S40: =Q40+R40 -> 8
A41: =ROW(A41)-28 -> 13 | B41: 00370071-005 | D41: 210-8625 | F41: AESSXF 0.3 Gr/R | I41: 내작 | J41: WIRE | N41: MTR | O41: 0.4075 | P41: =VLOOKUP($D41,'[1]250113_자재단가조회'!$D$2:$M$517,10,0) -> 60.65 | Q41: =ROUND(O41*P41,2) -> 24.71 | S41: =Q41+R41 -> 24.71 | AB41: 전선길이 220mm 증가
A42: =ROW(A42)-28 -> 14 | B42: 00370071-005 | D42: 251-3107 | F42: KH2000016-21 | I42: 내작 | J42: TERMINAL | N42: EA | O42: 1 | P42: =VLOOKUP($D42,'[1]250113_자재단가조회'!$D$2:$M$517,10,0) -> 8.5 | Q42: =ROUND(O42*P42,2) -> 8.5 | S42: =Q42+R42 -> 8.5
A43: =ROW(A43)-28 -> 15 | B43: 00370071-005 | D43: 251-2143 | F43: 731409-7 | I43: 내작 | J43: TERMINAL | N43: EA | O43: 1 | P43: =VLOOKUP($D43,'[1]250113_자재단가조회'!$D$2:$M$517,10,0) -> 8 | Q43: =ROUND(O43*P43,2) -> 8 | S43: =Q43+R43 -> 8
...

Sheet 18
A1: 원가계산서
A2: 작성일자 : 25.01.15 | C2: 작성자 : 남광표
A3: 차종 | B3: CE FL | D3: 고 객 품 번 | F3: 00363724 | H3: 경 림 품 번 | I3: WA-2312-4428 | K3: 품 명 | L3: CE FL RC OS STD NAS WIRE
A4: SOP | B4: 2025.05.15 | D4: 연 생 산 수 량 | H4: 고 객 사 | I4: SL 천안공장 | K4: EO NO | L4: DR-24069 | N4: EO 일자 | O4: 24.06.11
A6: 3. 원가 계산 정보
A7: 원 가 요 소 | C7: 계 산 수 식 | F7: 외작 | G7: 내작 | H7: 계 | I7: 협력사 구매가 | K7: 비고 | U7: 원 가 요 소 | W7: 외작 | X7: 내작 | Y7: 계 | Z7: 협력사 구매가
A8: 1. 재 료 비 | C8: 재료비 합계(내/외작) | F8: =SUMIF($M$29:$M$56,F$7,$S$29:$S$56) -> 311.08 | G8: =SUMIF($M$29:$M$56,G$7,$S$29:$S$56) -> 193.02 | H8: =+F8+G8 -> 504.1 | I8: =SUM($S$29:$S$56) -> 504.1 | U8: 1. 재 료 비 | W8: =SUMIF($T$29:$T$56,W$7,$Z$29:$Z$56) -> 0 | X8: =SUMIF($T$29:$T$56,X$7,$Z$29:$Z$56) -> 0 | Y8: =+W8+X8 -> 0 | Z8: =SUM($Z$29:$Z$56) -> 0
A9: 2. 가공비 | F9: =+F10+F11 -> 256.82 | G9: =+G10+G11 -> 65.66 | H9: =+F9+G9 -> 322.48 | I9: =SUM(I10:I11) -> 256.82 | U9: 2. 가공비 | W9: =+W10+W11 -> 0 | X9: =+X10+X11 -> 0 | Y9: =+W9+X9 -> 0 | Z9: =SUM(Z10:Z11) -> 0
A10: 2. 노 무 비 | C10: 노무비 합계(내/외작) | F10: =SUMIF($M$64:$M$72,F$7,$Q$64:$Q$72) -> 255.63 | G10: =SUMIF($M$64:$M$72,G$7,$Q$64:$Q$72) -> 55.11 | H10: =+F10+G10 -> 310.74 | I10: =SUMIF($M$64:$M$72,$F$7,$Q$64:$Q$72) -> 255.63 | U10: 2. 노 무 비 | W10: =SUMIF($T$64:$T$72,W$7,$X$64:$X$72) -> 0 | X10: =SUMIF($T$64:$T$72,X$7,$X$64:$X$72) -> 0 | Y10: =+W10+X10 -> 0 | Z10: =SUMIF($T$64:$T$72,$W$7,$X$64:$X$72) -> 0
A11: 3. 경 비 | C11: 경비 합계(내/외작) | F11: =SUMIF($M$64:$M$72,F$7,$R$64:$R$72) -> 1.19 | G11: =SUMIF($M$64:$M$72,G$7,$R$64:$R$72) -> 10.55 | H11: =+F11+G11 -> 11.74 | I11: =SUMIF($M$64:$M$72,$F$7,$R$64:$R$72) -> 1.19 | U11: 3. 경 비 | W11: =SUMIF($T$64:$T$72,W$7,$Y$64:$Y$72) -> 0 | X11: =SUMIF($T$64:$T$72,X$7,$Y$64:$Y$72) -> 0 | Y11: =+W11+X11 -> 0 | Z11: =SUMIF($T$64:$T$72,$W$7,$Y$64:$Y$72) -> 0
A12: 4. 제 조 원 가 | C12: ( 1 + 2 + 3 ) | F12: =+F8+F10+F11 -> 567.9 | G12: =+G8+G10+G11 -> 258.68 | H12: =+F12+G12 -> 826.58 | I12: =SUM(I11,I10,I8) -> 760.92 | U12: 4. 제 조 원 가 | W12: =+W8+W10+W11 -> 0 | X12: =+X8+X10+X11 -> 0 | Y12: =+W12+X12 -> 0 | Z12: =SUM(Z8,Z10,Z11) -> 0
A13: 5. 재 료 관 리 비 | C13: ( 1 ) X | D13: 0.01 | F13: =ROUND(+F8*$D13,2) -> 3.11 | G13: =ROUND(+G8*$D13,2) -> 1.93 | H13: =+F13+G13 -> 5.04 | I13: =ROUND(I8*$D13,2) -> 5.04 | U13: 5. 재 료 관 리 비 | W13: =ROUND(+W8*$D13,2) -> 0 | X13: =ROUND(+X8*$D13,2) -> 0 | Y13: =+W13+X13 -> 0 | Z13: =ROUND(Z8*$D13,2) -> 0
A14: 6. 일 반 관 리 비 | C14: ( 2+3 ) X | D14: 0.1 | F14: =ROUND((F10+F11)*$D14,2) -> 25.68 | G14: =ROUND((G10+G11)*$D14,2) -> 6.57 | H14: =+F14+G14 -> 32.25 | I14: =ROUND((I10+I11)*$D14,2) -> 25.68 | U14: 6. 일 반 관 리 비 | W14: =ROUND((W10+W11)*$D14,2) -> 0 | X14: =ROUND((X10+X11)*$D14,2) -> 0 | Y14: =+W14+X14 -> 0 | Z14: =ROUND((Z10+Z11)*$D14,2) -> 0
A15: 7. 불 량 비 | C15: ( 4 ) X | D15: 0.01 | F15: =ROUND(F12*$D15,2) -> 5.68 | G15: =ROUND(G12*$D15,2) -> 2.59 | H15: =+F15+G15 -> 8.27 | I15: =ROUND(I12*$D15,2) -> 7.61 | U15: 7. 불 량 비 | W15: =ROUND(W12*$D15,2) -> 0 | X15: =ROUND(X12*$D15,2) -> 0 | Y15: =+W15+X15 -> 0 | Z15: =ROUND(Z12*$D15,2) -> 0
A16: 8. 이 윤 | C16: ( 2 +3+ 6 ) X | D16: 0.1 | F16: =ROUND(SUM(F10,F11,F14)*$D16,2) -> 28.25 | G16: =ROUND(SUM(G10,G11,G14)*$D16,2) -> 7.22 | H16: =+F16+G16 -> 35.47 | I16: =ROUND((I10+I11+I14)*$D16,2) -> 28.25 | U16: 8. 이 윤 | W16: =ROUND(SUM(W10,W11,W14)*$D16,2) -> 0 | X16: =ROUND(SUM(X10,X11,X14)*$D16,2) -> 0 | Y16: =+W16+X16 -> 0 | Z16: =ROUND((Z10+Z11+Z14)*$D16,2) -> 0
A17: 9. 포 장 비 | C17: 별도 | U17: 9. 포 장 비
A18: 10. 운 반 비 | C18: 별도 | U18: 10. 운 반 비
A19: 11. 구 매 원 가 | C19: 별도 | F19: =SUM(F12:F18) -> 630.62 | G19: =SUM(G12:G18) -> 276.99 | H19: =SUM(H12:H18) -> 907.61 | I19: =SUM(I12:I18) -> 827.5 | U19: 11. 구 매 원 가 | W19: =SUM(W12:W18) -> 0 | X19: =SUM(X12:X18) -> 0 | Y19: =SUM(Y12:Y18) -> 0 | Z19: =SUM(Z12:Z18) -> 0
A20: 12. 설 계 시 험 비 | F20: =ROUND(+F19*$D20,2) -> 0 | G20: =ROUND(+G19*$D20,2) -> 0 | H20: =G20+F20 -> 0 | I20: =H20+G20 -> 0 | U20: 12. 설 계 시 험 비 | W20: 0 | X20: 0 | Y20: 0 | Z20: 0
A21: 13. 관 리 비 | F21: =ROUND(F19*$D21,2) -> 0 | G21: =ROUND(G19*$D21,2) -> 0 | H21: =SUM(H12:H18)*$D21 -> 0 | I21: =SUM(I12:I18)*$D21 -> 0 | U21: 13. 관 리 비 | W21: 0 | X21: 0 | Y21: 0 | Z21: 0
A22: 14. 총 원 가 | F22: =SUM(F19:F21) -> 630.62 | G22: =SUM(G19:G21) -> 276.99 | H22: =SUM(H19:H21) -> 907.61 | I22: =SUM(I19:I21) -> 827.5 | U22: 14. 총 원 가 | W22: =SUM(W19:W21) -> 0 | X22: =SUM(X19:X21) -> 0 | Y22: =SUM(Y19:Y21) -> 0 | Z22: =SUM(Z19:Z21) -> 0
A23: 판 매 가 | U23: 판 매 가
A26: 1. 재료비 상세내역
A27: NO | B27: 품 번 | D27: 품 번 | F27: 품 명 | I27: 규격 | M27: 내외작 | T27: 내외작 | AA27: 차이 | AB27: 비 고
B28: (절압품) | D28: (원재료) | F28: (원재료 품명) | N28: 단위 | O28: 수량 | P28: 단가 | Q28: 재료비 | R28: SCRAP비 | S28: 합계 | U28: 단위 | V28: 수량 | W28: 단가 | X28: 재료비 | Y28: SCRAP비 | Z28: 합계
A29: =ROW(A29)-28 -> 1 | B29: 00363724-001 | D29: 210-4531 | F29: AVSS 0.5 B/P | I29: WIRE | M29: 내작 | N29: MTR | O29: 0.168 | P29: =VLOOKUP($D29,[1]원자재_250115!$D:$G,4,) -> 54.6 | Q29: =ROUND(O29*P29,2) -> 9.17 | S29: =Q29+R29 -> 9.17 | X29: =ROUND(V29*W29,2) -> 0 | Z29: =X29+Y29 -> 0
A30: =ROW(A30)-28 -> 2 | B30: 00363724-001 | D30: 251-8319 | F30: K200294-30 | I30: TERMINAL | M30: 내작 | N30: EA | O30: 1 | P30: =VLOOKUP($D30,[1]원자재_250115!$D:$G,4,) -> 5.8 | Q30: =ROUND(O30*P30,2) -> 5.8 | S30: =Q30+R30 -> 5.8 | X30: =ROUND(V30*W30,2) -> 0 | Z30: =X30+Y30 -> 0
A31: =ROW(A31)-28 -> 3 | B31: 00363724-001 | D31: MT-0400-0066 | F31: KM025BWP M TML(L) | I31: TERMINAL | M31: 내작 | N31: EA | O31: 1 | P31: =VLOOKUP($D31,[1]표지!$Z$81:$AB$97,3,) -> 7.2 | Q31: =ROUND(O31*P31,2) -> 7.2 | S31: =Q31+R31 -> 7.2 | X31: =ROUND(V31*W31,2) -> 0 | Z31: =X31+Y31 -> 0
A32: =ROW(A32)-28 -> 4 | B32: 00363724-001 | D32: 250-4428 | F32: KM025WP-W/SEAL(L) | I32: SEAL | M32: 내작 | N32: EA | O32: 1 | P32: =VLOOKUP($D32,[1]원자재_250115!$D:$G,4,) -> 10 | Q32: =ROUND(O32*P32,2) -> 10 | S32: =Q32+R32 -> 10 | X32: =ROUND(V32*W32,2) -> 0 | Z32: =X32+Y32 -> 0
A33: =ROW(A33)-28 -> 5 | B33: 00363724-002 | D33: 210-4518 | F33: AVSS 0.5 B/R | I33: WIRE | M33: 내작 | N33: MTR | O33: 0.168 | P33: =VLOOKUP($D33,[1]원자재_250115!$D:$G,4,) -> 54.6 | Q33: =ROUND(O33*P33,2) -> 9.17 | S33: =Q33+R33 -> 9.17 | X33: =ROUND(V33*W33,2) -> 0 | Z33: =X33+Y33 -> 0
A34: =ROW(A34)-28 -> 6 | B34: 00363724-002 | D34: 251-8319 | F34: K200294-30 | I34: TERMINAL | M34: 내작 | N34: EA | O34: 1 | P34: =VLOOKUP($D34,[1]원자재_250115!$D:$G,4,) -> 5.8 | Q34: =ROUND(O34*P34,2) -> 5.8 | S34: =Q34+R34 -> 5.8 | X34: =ROUND(V34*W34,2) -> 0 | Z34: =X34+Y34 -> 0
A35: =ROW(A35)-28 -> 7 | B35: 00363724-002 | D35: MT-0400-0066 | F35: KM025BWP M TML(L) | I35: TERMINAL | M35: 내작 | N35: EA | O35: 1 | P35: =VLOOKUP($D35,[1]표지!$Z$81:$AB$97,3,) -> 7.2 | Q35: =ROUND(O35*P35,2) -> 7.2 | S35: =Q35+R35 -> 7.2 | X35: =ROUND(V35*W35,2) -> 0 | Z35: =X35+Y35 -> 0
A36: =ROW(A36)-28 -> 8 | B36: 00363724-002 | D36: 250-4428 | F36: KM025WP-W/SEAL(L) | I36: SEAL | M36: 내작 | N36: EA | O36: 1 | P36: =VLOOKUP($D36,[1]원자재_250115!$D:$G,4,) -> 10 | Q36: =ROUND(O36*P36,2) -> 10 | S36: =Q36+R36 -> 10 | X36: =ROUND(V36*W36,2) -> 0 | Z36: =X36+Y36 -> 0
A37: =ROW(A37)-28 -> 9 | B37: 00363724-003 | D37: 210-4530 | F37: AVSS 0.5 B/O | I37: WIRE | M37: 내작 | N37: MTR | O37: 0.168 | P37: =VLOOKUP($D37,[1]원자재_250115!$D:$G,4,) -> 54.6 | Q37: =ROUND(O37*P37,2) -> 9.17 | S37: =Q37+R37 -> 9.17 | X37: =ROUND(V37*W37,2) -> 0 | Z37: =X37+Y37 -> 0
A38: =ROW(A38)-28 -> 10 | B38: 00363724-003 | D38: 251-8319 | F38: K200294-30 | I38: TERMINAL | M38: 내작 | N38: EA | O38: 1 | P38: =VLOOKUP($D38,[1]원자재_250115!$D:$G,4,) -> 5.8 | Q38: =ROUND(O38*P38,2) -> 5.8 | S38: =Q38+R38 -> 5.8 | X38: =ROUND(V38*W38,2) -> 0 | Z38: =X38+Y38 -> 0
A39: =ROW(A39)-28 -> 11 | B39: 00363724-003 | D39: MT-0400-0066 | F39: KM025BWP M TML(L) | I39: TERMINAL | M39: 내작 | N39: EA | O39: 1 | P39: =VLOOKUP($D39,[1]표지!$Z$81:$AB$97,3,) -> 7.2 | Q39: =ROUND(O39*P39,2) -> 7.2 | S39: =Q39+R39 -> 7.2 | X39: =ROUND(V39*W39,2) -> 0 | Z39: =X39+Y39 -> 0
A40: =ROW(A40)-28 -> 12 | B40: 00363724-003 | D40: 250-4428 | F40: KM025WP-W/SEAL(L) | I40: SEAL | M40: 내작 | N40: EA | O40: 1 | P40: =VLOOKUP($D40,[1]원자재_250115!$D:$G,4,) -> 10 | Q40: =ROUND(O40*P40,2) -> 10 | S40: =Q40+R40 -> 10 | X40: =ROUND(V40*W40,2) -> 0 | Z40: =X40+Y40 -> 0
A41: =ROW(A41)-28 -> 13 | B41: 00363724-004 | D41: 210-4512 | F41: AVSS 0.5 B/Y | I41: WIRE | M41: 내작 | N41: MTR | O41: 0.168 | P41: =VLOOKUP($D41,[1]원자재_250115!$D:$G,4,) -> 54.6 | Q41: =ROUND(O41*P41,2) -> 9.17 | S41: =Q41+R41 -> 9.17 | X41: =ROUND(V41*W41,2) -> 0 | Z41: =X41+Y41 -> 0
A42: =ROW(A42)-28 -> 14 | B42: 00363724-004 | D42: 251-8319 | F42: K200294-30 | I42: TERMINAL | M42: 내작 | N42: EA | O42: 1 | P42: =VLOOKUP($D42,[1]원자재_250115!$D:$G,4,) -> 5.8 | Q42: =ROUND(O42*P42,2) -> 5.8 | S42: =Q42+R42 -> 5.8 | X42: =ROUND(V42*W42,2) -> 0 | Z42: =X42+Y42 -> 0
A43: =ROW(A43)-28 -> 15 | B43: 00363724-004 | D43: MT-0400-0066 | F43: KM025BWP M TML(L) | I43: TERMINAL | M43: 내작 | N43: EA | O43: 1 | P43: =VLOOKUP($D43,[1]표지!$Z$81:$AB$97,3,) -> 7.2 | Q43: =ROUND(O43*P43,2) -> 7.2 | S43: =Q43+R43 -> 7.2 | X43: =ROUND(V43*W43,2) -> 0 | Z43: =X43+Y43 -> 0
...
